<?xml version="1.0" ?>
<!-- =================================================================================== -->
<!-- |    This document was autogenerated by xacro from sobit_pro.urdf.xacro           | -->
<!-- |    EDITING THIS FILE BY HAND IS NOT RECOMMENDED                                 | -->
<!-- =================================================================================== -->
<robot name="sobit_pro">
  <material name="wheel">
    <color rgba="0.2 0.2 0.2 1.0"/>
  </material>
  <material name="black">
    <color rgba="0.1 0.1 0.1 1.0"/>
  </material>
  <material name="red">
    <color rgba="1.0 0.0 0.0 1.0"/>
  </material>
  <material name="green">
    <color rgba="0.0 1.0 0.0 1.0"/>
  </material>
  <material name="blue">
    <color rgba="0.0 0.0 1.0 1.0"/>
  </material>
  <material name="white">
    <color rgba="1.0 1.0 1.0 1.0"/>
  </material>
  <material name="grey">
    <color rgba="0.3 0.3 0.3 1.0"/>
  </material>
  <material name="dark_grey">
    <color rgba="0.175 0.175 0.175 1.0"/>
  </material>
  <material name="aluminum">
    <color rgba="0.5 0.5 0.5 1"/>
  </material>
  <material name="plastic">
    <color rgba="0.1 0.1 0.1 1"/>
  </material>
  <link name="base_footprint"/>
  <joint name="base_joint" type="fixed">
    <parent link="base_footprint"/>
    <child link="base_link"/>
    <origin rpy="0.0 0.0 0.0" xyz="0 0 0.177"/>
  </joint>
  <link name="base_link"/>
  <joint name="plate_bottom_joint" type="fixed">
    <origin rpy="0.0 0.0 0.0" xyz="0.0 0.0 0.0"/>
    <parent link="base_link"/>
    <child link="plate_bottom_link"/>
  </joint>
  <link name="plate_bottom_link">
    <visual>
      <origin rpy="0.0 0.0 0.0" xyz="0.0 0.0 0.0"/>
      <geometry>
        <mesh filename="package://sobit_pro_description/meshes/body/plate_bottom.stl" scale="0.001 0.001 0.001"/>
      </geometry>
      <material name="black"/>
    </visual>
    <collision>
      <origin rpy="0.0 0.0 0.0" xyz="0.0 0.0 -0.0045"/>
      <geometry>
        <box size="0.3 0.3 0.009"/>
      </geometry>
    </collision>
    <inertial>
      <origin rpy="0.0 0.0 0.0" xyz="0.0 0.0 -0.0045"/>
      <mass value="0.08"/>
      <inertia ixx="0.0006005399999999999" ixy="0.0" ixz="0.0" iyy="0.0006005399999999999" iyz="0.0" izz="0.0012"/>
    </inertial>
  </link>
  <joint name="plate_middle_joint" type="fixed">
    <origin rpy="0.0 0.0 0.0" xyz="0.0 0.0 0.064"/>
    <parent link="plate_bottom_link"/>
    <child link="plate_middle_link"/>
  </joint>
  <link name="plate_middle_link">
    <visual>
      <origin rpy="0.0 0.0 0.0" xyz="0.0 0.0 0.0"/>
      <geometry>
        <mesh filename="package://sobit_pro_description/meshes/body/plate_middle.stl" scale="0.001 0.001 0.001"/>
      </geometry>
      <material name="black"/>
    </visual>
    <collision>
      <origin rpy="0.0 0.0 0.0" xyz="0.0 0.0 -0.0045"/>
      <geometry>
        <box size="0.3 0.3 0.009"/>
      </geometry>
    </collision>
    <inertial>
      <origin rpy="0.0 0.0 0.0" xyz="0.0 0.0 -0.0045"/>
      <mass value="0.08"/>
      <inertia ixx="0.0006005399999999999" ixy="0.0" ixz="0.0" iyy="0.0006005399999999999" iyz="0.0" izz="0.0012"/>
    </inertial>
  </link>
  <joint name="plate_top_joint" type="fixed">
    <origin rpy="0.0 0.0 0.0" xyz="0.0 0.0 0.4800"/>
    <parent link="plate_middle_link"/>
    <child link="plate_top_link"/>
  </joint>
  <link name="plate_top_link">
    <visual>
      <origin rpy="0.0 0.0 1.570796326795" xyz="0.0 0.0 0.0"/>
      <geometry>
        <mesh filename="package://sobit_pro_description/meshes/body/plate_top.stl" scale="0.001 0.001 0.001"/>
      </geometry>
      <material name="black"/>
    </visual>
    <collision>
      <origin rpy="0.0 0.0 0.0" xyz="0.0 0.0 -0.0045"/>
      <geometry>
        <box size="0.3 0.3 0.009"/>
      </geometry>
    </collision>
    <inertial>
      <origin rpy="0.0 0.0 0.0" xyz="0.0 0.0 -0.0045"/>
      <mass value="0.08"/>
      <inertia ixx="0.0006005399999999999" ixy="0.0" ixz="0.0" iyy="0.0006005399999999999" iyz="0.0" izz="0.0012"/>
    </inertial>
  </link>
  <joint name="wheel_f_l_steer_base_joint" type="fixed">
    <origin rpy="0.0 0.0 0.7853981633975" xyz="0.14849242404917498 0.14849242404917498 -0.019"/>
    <parent link="plate_middle_link"/>
    <child link="wheel_f_l_steer_base_link"/>
  </joint>
  <link name="wheel_f_l_steer_base_link">
    <visual>
      <origin rpy="1.570796326795 0.0 1.570796326795" xyz="0.0 0.0 0.0"/>
      <geometry>
        <mesh filename="package://sobit_pro_description/meshes/wheel/wheel_base.stl" scale="0.001 0.001 0.001"/>
      </geometry>
      <material name="black"/>
    </visual>
    <collision>
      <origin rpy="0.0 0.0 0.0" xyz="-0.013745 0.0 -0.032"/>
      <geometry>
        <box size="0.05525 0.0285 0.084"/>
      </geometry>
    </collision>
    <inertial>
      <origin rpy="0.0 0.0 0.0" xyz="-0.013745 0.0 -0.032"/>
      <mass value="1"/>
      <inertia ixx="0.0008423802083333334" ixy="0.0" ixz="0.0" iyy="0.0006556875" iyz="0.0" izz="0.00032206770833333333"/>
    </inertial>
  </link>
  <joint name="wheel_b_l_steer_base_joint" type="fixed">
    <origin rpy="0.0 0.0 2.3561944901925003" xyz="-0.14849242404917498 0.14849242404917498 -0.019"/>
    <parent link="plate_middle_link"/>
    <child link="wheel_b_l_steer_base_link"/>
  </joint>
  <link name="wheel_b_l_steer_base_link">
    <visual>
      <origin rpy="1.570796326795 0.0 1.570796326795" xyz="0.0 0.0 0.0"/>
      <geometry>
        <mesh filename="package://sobit_pro_description/meshes/wheel/wheel_base.stl" scale="0.001 0.001 0.001"/>
      </geometry>
      <material name="black"/>
    </visual>
    <collision>
      <origin rpy="0.0 0.0 0.0" xyz="-0.013745 0.0 -0.032"/>
      <geometry>
        <box size="0.05525 0.0285 0.084"/>
      </geometry>
    </collision>
    <inertial>
      <origin rpy="0.0 0.0 0.0" xyz="-0.013745 0.0 -0.032"/>
      <mass value="1"/>
      <inertia ixx="0.0008423802083333334" ixy="0.0" ixz="0.0" iyy="0.0006556875" iyz="0.0" izz="0.00032206770833333333"/>
    </inertial>
  </link>
  <joint name="wheel_b_r_steer_base_joint" type="fixed">
    <origin rpy="0.0 0.0 3.9269908169875" xyz="-0.14849242404917498 -0.14849242404917498 -0.019"/>
    <parent link="plate_middle_link"/>
    <child link="wheel_b_r_steer_base_link"/>
  </joint>
  <link name="wheel_b_r_steer_base_link">
    <visual>
      <origin rpy="1.570796326795 0.0 1.570796326795" xyz="0.0 0.0 0.0"/>
      <geometry>
        <mesh filename="package://sobit_pro_description/meshes/wheel/wheel_base.stl" scale="0.001 0.001 0.001"/>
      </geometry>
      <material name="black"/>
    </visual>
    <collision>
      <origin rpy="0.0 0.0 0.0" xyz="-0.013745 0.0 -0.032"/>
      <geometry>
        <box size="0.05525 0.0285 0.084"/>
      </geometry>
    </collision>
    <inertial>
      <origin rpy="0.0 0.0 0.0" xyz="-0.013745 0.0 -0.032"/>
      <mass value="1"/>
      <inertia ixx="0.0008423802083333334" ixy="0.0" ixz="0.0" iyy="0.0006556875" iyz="0.0" izz="0.00032206770833333333"/>
    </inertial>
  </link>
  <joint name="wheel_f_r_steer_base_joint" type="fixed">
    <origin rpy="0.0 0.0 5.4977871437825" xyz="0.14849242404917498 -0.14849242404917498 -0.019"/>
    <parent link="plate_middle_link"/>
    <child link="wheel_f_r_steer_base_link"/>
  </joint>
  <link name="wheel_f_r_steer_base_link">
    <visual>
      <origin rpy="1.570796326795 0.0 1.570796326795" xyz="0.0 0.0 0.0"/>
      <geometry>
        <mesh filename="package://sobit_pro_description/meshes/wheel/wheel_base.stl" scale="0.001 0.001 0.001"/>
      </geometry>
      <material name="black"/>
    </visual>
    <collision>
      <origin rpy="0.0 0.0 0.0" xyz="-0.013745 0.0 -0.032"/>
      <geometry>
        <box size="0.05525 0.0285 0.084"/>
      </geometry>
    </collision>
    <inertial>
      <origin rpy="0.0 0.0 0.0" xyz="-0.013745 0.0 -0.032"/>
      <mass value="1"/>
      <inertia ixx="0.0008423802083333334" ixy="0.0" ixz="0.0" iyy="0.0006556875" iyz="0.0" izz="0.00032206770833333333"/>
    </inertial>
  </link>
  <joint name="wheel_f_l_steer_joint" type="revolute">
    <origin rpy="0.0 0.0 0.0" xyz="0.013875 0.0 -0.032"/>
    <parent link="wheel_f_l_steer_base_link"/>
    <child link="wheel_f_l_steer_link"/>
    <axis xyz="0.0 0.0 1.0 "/>
    <limit effort="4.1" lower="-1.570796326795" upper="1.570796326795" velocity="4.796165"/>
    <!-- <dynamics damping="0.2" friction="0" /> -->
  </joint>
  <link name="wheel_f_l_steer_link">
    <visual>
      <origin rpy="1.570796326795 0.0 1.570796326795" xyz="0.0 0.0 0.0"/>
      <geometry>
        <mesh filename="package://sobit_pro_description/meshes/wheel/wheel_steer.stl" scale="0.001 0.001 0.001"/>
      </geometry>
      <material name="black"/>
    </visual>
    <collision>
      <origin rpy="0.0 0.0 0.0" xyz="0.046200000000000005 0.0 -0.056400000000000006"/>
      <geometry>
        <box size="0.0436 0.0495 0.1766"/>
      </geometry>
    </collision>
    <inertial>
      <origin rpy="0.0 0.0 0.0" xyz="0.046200000000000005 0.0 -0.056400000000000006"/>
      <mass value="1"/>
      <inertia ixx="0.002757376666666667" ixy="0.0" ixz="0.0" iyy="0.0028031508333333337" iyz="0.0" izz="0.00036260083333333336"/>
    </inertial>
  </link>
  <joint name="wheel_b_l_steer_joint" type="revolute">
    <origin rpy="0.0 0.0 0.0" xyz="0.013875 0.0 -0.032"/>
    <parent link="wheel_b_l_steer_base_link"/>
    <child link="wheel_b_l_steer_link"/>
    <axis xyz="0.0 0.0 1.0 "/>
    <limit effort="4.1" lower="-1.570796326795" upper="1.570796326795" velocity="4.796165"/>
    <!-- <dynamics damping="0.2" friction="0" /> -->
  </joint>
  <link name="wheel_b_l_steer_link">
    <visual>
      <origin rpy="1.570796326795 0.0 1.570796326795" xyz="0.0 0.0 0.0"/>
      <geometry>
        <mesh filename="package://sobit_pro_description/meshes/wheel/wheel_steer.stl" scale="0.001 0.001 0.001"/>
      </geometry>
      <material name="black"/>
    </visual>
    <collision>
      <origin rpy="0.0 0.0 0.0" xyz="0.046200000000000005 0.0 -0.056400000000000006"/>
      <geometry>
        <box size="0.0436 0.0495 0.1766"/>
      </geometry>
    </collision>
    <inertial>
      <origin rpy="0.0 0.0 0.0" xyz="0.046200000000000005 0.0 -0.056400000000000006"/>
      <mass value="1"/>
      <inertia ixx="0.002757376666666667" ixy="0.0" ixz="0.0" iyy="0.0028031508333333337" iyz="0.0" izz="0.00036260083333333336"/>
    </inertial>
  </link>
  <joint name="wheel_b_r_steer_joint" type="revolute">
    <origin rpy="0.0 0.0 0.0" xyz="0.013875 0.0 -0.032"/>
    <parent link="wheel_b_r_steer_base_link"/>
    <child link="wheel_b_r_steer_link"/>
    <axis xyz="0.0 0.0 1.0 "/>
    <limit effort="4.1" lower="-1.570796326795" upper="1.570796326795" velocity="4.796165"/>
    <!-- <dynamics damping="0.2" friction="0" /> -->
  </joint>
  <link name="wheel_b_r_steer_link">
    <visual>
      <origin rpy="1.570796326795 0.0 1.570796326795" xyz="0.0 0.0 0.0"/>
      <geometry>
        <mesh filename="package://sobit_pro_description/meshes/wheel/wheel_steer.stl" scale="0.001 0.001 0.001"/>
      </geometry>
      <material name="black"/>
    </visual>
    <collision>
      <origin rpy="0.0 0.0 0.0" xyz="0.046200000000000005 0.0 -0.056400000000000006"/>
      <geometry>
        <box size="0.0436 0.0495 0.1766"/>
      </geometry>
    </collision>
    <inertial>
      <origin rpy="0.0 0.0 0.0" xyz="0.046200000000000005 0.0 -0.056400000000000006"/>
      <mass value="1"/>
      <inertia ixx="0.002757376666666667" ixy="0.0" ixz="0.0" iyy="0.0028031508333333337" iyz="0.0" izz="0.00036260083333333336"/>
    </inertial>
  </link>
  <joint name="wheel_f_r_steer_joint" type="revolute">
    <origin rpy="0.0 0.0 0.0" xyz="0.013875 0.0 -0.032"/>
    <parent link="wheel_f_r_steer_base_link"/>
    <child link="wheel_f_r_steer_link"/>
    <axis xyz="0.0 0.0 1.0 "/>
    <limit effort="4.1" lower="-1.570796326795" upper="1.570796326795" velocity="4.796165"/>
    <!-- <dynamics damping="0.2" friction="0" /> -->
  </joint>
  <link name="wheel_f_r_steer_link">
    <visual>
      <origin rpy="1.570796326795 0.0 1.570796326795" xyz="0.0 0.0 0.0"/>
      <geometry>
        <mesh filename="package://sobit_pro_description/meshes/wheel/wheel_steer.stl" scale="0.001 0.001 0.001"/>
      </geometry>
      <material name="black"/>
    </visual>
    <collision>
      <origin rpy="0.0 0.0 0.0" xyz="0.046200000000000005 0.0 -0.056400000000000006"/>
      <geometry>
        <box size="0.0436 0.0495 0.1766"/>
      </geometry>
    </collision>
    <inertial>
      <origin rpy="0.0 0.0 0.0" xyz="0.046200000000000005 0.0 -0.056400000000000006"/>
      <mass value="1"/>
      <inertia ixx="0.002757376666666667" ixy="0.0" ixz="0.0" iyy="0.0028031508333333337" iyz="0.0" izz="0.00036260083333333336"/>
    </inertial>
  </link>
  <joint name="wheel_f_l_drive_joint" type="continuous">
    <origin rpy="0.0 0.0 0.0" xyz="0.0219 0.0 -0.118"/>
    <parent link="wheel_f_l_steer_link"/>
    <child link="wheel_f_l_drive_link"/>
    <axis xyz="-1.0 0.0 0.0 "/>
    <limit effort="3.0" velocity="7.913672"/>
  </joint>
  <link name="wheel_f_l_drive_link">
    <visual>
      <origin rpy="1.570796326795 0.0 4.7123889803850005" xyz="0.0 0.0 0.0"/>
      <geometry>
        <mesh filename="package://sobit_pro_description/meshes/wheel/wheel_drive.stl" scale="0.001 0.001 0.001"/>
      </geometry>
      <material name="wheel"/>
    </visual>
    <collision>
      <origin rpy="1.570796326795 0.0 4.7123889803850005" xyz="-0.02 0.0 0.0"/>
      <geometry>
        <cylinder length="0.029" radius="0.072"/>
      </geometry>
    </collision>
    <inertial>
      <origin rpy="0.0 0.0 0.0" xyz="-0.02 0.0 0.0"/>
      <mass value="1"/>
      <inertia ixx="0.0025919999999999997" ixy="0.0" ixz="0.0" iyy="0.001366083333333333" iyz="0.0" izz="0.001366083333333333"/>
    </inertial>
  </link>
  <joint name="wheel_b_l_drive_joint" type="continuous">
    <origin rpy="0.0 0.0 0.0" xyz="0.0219 0.0 -0.118"/>
    <parent link="wheel_b_l_steer_link"/>
    <child link="wheel_b_l_drive_link"/>
    <axis xyz="-1.0 0.0 0.0 "/>
    <limit effort="3.0" velocity="7.913672"/>
  </joint>
  <link name="wheel_b_l_drive_link">
    <visual>
      <origin rpy="1.570796326795 0.0 4.7123889803850005" xyz="0.0 0.0 0.0"/>
      <geometry>
        <mesh filename="package://sobit_pro_description/meshes/wheel/wheel_drive.stl" scale="0.001 0.001 0.001"/>
      </geometry>
      <material name="wheel"/>
    </visual>
    <collision>
      <origin rpy="1.570796326795 0.0 4.7123889803850005" xyz="-0.02 0.0 0.0"/>
      <geometry>
        <cylinder length="0.029" radius="0.072"/>
      </geometry>
    </collision>
    <inertial>
      <origin rpy="0.0 0.0 0.0" xyz="-0.02 0.0 0.0"/>
      <mass value="1"/>
      <inertia ixx="0.0025919999999999997" ixy="0.0" ixz="0.0" iyy="0.001366083333333333" iyz="0.0" izz="0.001366083333333333"/>
    </inertial>
  </link>
  <joint name="wheel_b_r_drive_joint" type="continuous">
    <origin rpy="0.0 0.0 0.0" xyz="0.0219 0.0 -0.118"/>
    <parent link="wheel_b_r_steer_link"/>
    <child link="wheel_b_r_drive_link"/>
    <axis xyz="-1.0 0.0 0.0 "/>
    <limit effort="3.0" velocity="7.913672"/>
  </joint>
  <link name="wheel_b_r_drive_link">
    <visual>
      <origin rpy="1.570796326795 0.0 4.7123889803850005" xyz="0.0 0.0 0.0"/>
      <geometry>
        <mesh filename="package://sobit_pro_description/meshes/wheel/wheel_drive.stl" scale="0.001 0.001 0.001"/>
      </geometry>
      <material name="wheel"/>
    </visual>
    <collision>
      <origin rpy="1.570796326795 0.0 4.7123889803850005" xyz="-0.02 0.0 0.0"/>
      <geometry>
        <cylinder length="0.029" radius="0.072"/>
      </geometry>
    </collision>
    <inertial>
      <origin rpy="0.0 0.0 0.0" xyz="-0.02 0.0 0.0"/>
      <mass value="1"/>
      <inertia ixx="0.0025919999999999997" ixy="0.0" ixz="0.0" iyy="0.001366083333333333" iyz="0.0" izz="0.001366083333333333"/>
    </inertial>
  </link>
  <joint name="wheel_f_r_drive_joint" type="continuous">
    <origin rpy="0.0 0.0 0.0" xyz="0.0219 0.0 -0.118"/>
    <parent link="wheel_f_r_steer_link"/>
    <child link="wheel_f_r_drive_link"/>
    <axis xyz="-1.0 0.0 0.0 "/>
    <limit effort="3.0" velocity="7.913672"/>
  </joint>
  <link name="wheel_f_r_drive_link">
    <visual>
      <origin rpy="1.570796326795 0.0 4.7123889803850005" xyz="0.0 0.0 0.0"/>
      <geometry>
        <mesh filename="package://sobit_pro_description/meshes/wheel/wheel_drive.stl" scale="0.001 0.001 0.001"/>
      </geometry>
      <material name="wheel"/>
    </visual>
    <collision>
      <origin rpy="1.570796326795 0.0 4.7123889803850005" xyz="-0.02 0.0 0.0"/>
      <geometry>
        <cylinder length="0.029" radius="0.072"/>
      </geometry>
    </collision>
    <inertial>
      <origin rpy="0.0 0.0 0.0" xyz="-0.02 0.0 0.0"/>
      <mass value="1"/>
      <inertia ixx="0.0025919999999999997" ixy="0.0" ixz="0.0" iyy="0.001366083333333333" iyz="0.0" izz="0.001366083333333333"/>
    </inertial>
  </link>
  <transmission name="wheel_f_l_steer_joint_transmission">
    <type>transmission_interface/SimpleTransmission</type>
    <joint name="wheel_f_l_steer_joint">
      <hardwareInterface>hardware_interface/PositionJointInterface</hardwareInterface>
    </joint>
    <actuator name="wheel_f_l_steer_joint_actuator">
      <hardwareInterface>hardware_interface/PositionJointInterface</hardwareInterface>
      <mechanicalReduction>1</mechanicalReduction>
    </actuator>
  </transmission>
  <transmission name="wheel_f_r_steer_joint_transmission">
    <type>transmission_interface/SimpleTransmission</type>
    <joint name="wheel_f_r_steer_joint">
      <hardwareInterface>hardware_interface/PositionJointInterface</hardwareInterface>
    </joint>
    <actuator name="wheel_f_r_steer_joint_actuator">
      <hardwareInterface>hardware_interface/PositionJointInterface</hardwareInterface>
      <mechanicalReduction>1</mechanicalReduction>
    </actuator>
  </transmission>
  <transmission name="wheel_b_l_steer_joint_transmission">
    <type>transmission_interface/SimpleTransmission</type>
    <joint name="wheel_b_l_steer_joint">
      <hardwareInterface>hardware_interface/PositionJointInterface</hardwareInterface>
    </joint>
    <actuator name="wheel_b_l_steer_joint_actuator">
      <hardwareInterface>hardware_interface/PositionJointInterface</hardwareInterface>
      <mechanicalReduction>1</mechanicalReduction>
    </actuator>
  </transmission>
  <transmission name="wheel_b_r_steer_joint_transmission">
    <type>transmission_interface/SimpleTransmission</type>
    <joint name="wheel_b_r_steer_joint">
      <hardwareInterface>hardware_interface/PositionJointInterface</hardwareInterface>
    </joint>
    <actuator name="wheel_b_r_steer_joint_actuator">
      <hardwareInterface>hardware_interface/PositionJointInterface</hardwareInterface>
      <mechanicalReduction>1</mechanicalReduction>
    </actuator>
  </transmission>
  <transmission name="wheel_f_l_drive_joint_transmission">
    <type>transmission_interface/SimpleTransmission</type>
    <joint name="wheel_f_l_drive_joint">
      <hardwareInterface>hardware_interface/VelocityJointInterface</hardwareInterface>
    </joint>
    <actuator name="wheel_f_l_drive_joint_actuator">
      <hardwareInterface>hardware_interface/VelocityJointInterface</hardwareInterface>
      <mechanicalReduction>1</mechanicalReduction>
    </actuator>
  </transmission>
  <transmission name="wheel_f_r_drive_joint_transmission">
    <type>transmission_interface/SimpleTransmission</type>
    <joint name="wheel_f_r_drive_joint">
      <hardwareInterface>hardware_interface/VelocityJointInterface</hardwareInterface>
    </joint>
    <actuator name="wheel_f_r_drive_joint_actuator">
      <hardwareInterface>hardware_interface/VelocityJointInterface</hardwareInterface>
      <mechanicalReduction>1</mechanicalReduction>
    </actuator>
  </transmission>
  <transmission name="wheel_b_l_drive_joint_transmission">
    <type>transmission_interface/SimpleTransmission</type>
    <joint name="wheel_b_l_drive_joint">
      <hardwareInterface>hardware_interface/VelocityJointInterface</hardwareInterface>
    </joint>
    <actuator name="wheel_b_l_drive_joint_actuator">
      <hardwareInterface>hardware_interface/VelocityJointInterface</hardwareInterface>
      <mechanicalReduction>1</mechanicalReduction>
    </actuator>
  </transmission>
  <transmission name="wheel_b_r_drive_joint_transmission">
    <type>transmission_interface/SimpleTransmission</type>
    <joint name="wheel_b_r_drive_joint">
      <hardwareInterface>hardware_interface/VelocityJointInterface</hardwareInterface>
    </joint>
    <actuator name="wheel_b_r_drive_joint_actuator">
      <hardwareInterface>hardware_interface/VelocityJointInterface</hardwareInterface>
      <mechanicalReduction>1</mechanicalReduction>
    </actuator>
  </transmission>
  <joint name="cover_joint" type="fixed">
    <origin rpy="0.0 0.0 0.0" xyz="0.179108 0.0 -0.034"/>
    <parent link="plate_top_link"/>
    <child link="cover_link"/>
  </joint>
  <link name="cover_link">
    <visual>
      <origin rpy="1.570796326795 0.0 1.570796326795" xyz="0.0 0.0 0.0"/>
      <geometry>
        <mesh filename="package://sobit_pro_description/meshes/body/cover.stl" scale="0.001 0.001 0.001"/>
      </geometry>
      <material name="blue"/>
    </visual>
    <collision>
      <origin rpy="0.0 0.0 0.0" xyz="-0.17893 0.0 -0.2105"/>
      <geometry>
        <box size="0.35786 0.3965 0.489"/>
      </geometry>
    </collision>
    <inertial>
      <origin rpy="0.0 0.0 0.0" xyz="-0.17893 0.0 -0.2105"/>
      <mass value="0.732"/>
      <inertia ixx="0.0223982715556" ixy="0.0" ixz="0.0" iyy="0.02417632825" iyz="0.0" izz="0.017401837805600003"/>
    </inertial>
  </link>
  <joint name="back_base_joint" type="fixed">
    <parent link="plate_top_link"/>
    <child link="back_base_link"/>
    <origin rpy="0.0 0.0 0.0" xyz="0.0 0.0 0.0"/>
  </joint>
  <link name="back_base_link">
    <visual>
      <origin rpy="0.0 0.0 3.14159265359" xyz="0.0 0.0 0.0"/>
      <geometry>
        <mesh filename="package://sobit_pro_description/meshes/back/back_base.stl" scale="0.001 0.001 0.001"/>
      </geometry>
      <material name="grey"/>
    </visual>
    <collision>
      <origin rpy="0.0 0.0 0.0" xyz="0.0 0.0 0.2585"/>
      <geometry>
        <box size="0.02 0.02 0.517"/>
      </geometry>
    </collision>
    <inertial>
      <origin rpy="0.0 0.0 0.0" xyz="0.0 0.0 0.2585"/>
      <mass value="0.5"/>
      <inertia ixx="0.011153708333333333" ixy="0.0" ixz="0.0" iyy="0.011153708333333333" iyz="0.0" izz="3.3333333333333335e-05"/>
    </inertial>
  </link>
  <joint name="head_base_joint" type="fixed">
    <parent link="back_base_link"/>
    <child link="head_base_link"/>
    <origin rpy="0.0 0.0 0.0" xyz="0.0900 0.0 0.5270"/>
  </joint>
  <link name="head_base_link">
    <visual>
      <origin rpy="1.570796326795 0.0 1.570796326795" xyz="0.0 0.0 0.0"/>
      <geometry>
        <mesh filename="package://sobit_pro_description/meshes/head/head_camera_base.stl" scale="0.001 0.001 0.001"/>
      </geometry>
      <material name="black"/>
    </visual>
    <collision>
      <origin rpy="0.0 0.0 0.0" xyz="-0.024375 0.0 0.0"/>
      <geometry>
        <box size="0.15125 0.0285 0.044"/>
      </geometry>
    </collision>
    <inertial>
      <origin rpy="0.0 0.0 0.0" xyz="-0.024375 0.0 0.0"/>
      <mass value="0.08"/>
      <inertia ixx="0.00016541708333333332" ixy="0.0" ixz="0.0" iyy="1.8321666666666664e-05" iyz="0.0" izz="0.00015792541666666667"/>
    </inertial>
  </link>
  <joint name="head_pan_joint" type="revolute">
    <parent link="head_base_link"/>
    <child link="head_pan_link"/>
    <origin rpy="0.0 0.0 0.0" xyz="0.03985 0.0 0.0190"/>
    <axis xyz="0 0 1"/>
    <limit effort="4.1" lower="-1.570796326795" upper="1.570796326795" velocity="4.796165"/>
  </joint>
  <link name="head_pan_link">
    <visual>
      <origin rpy="0.0 0.0 1.570796326795" xyz="0.0 0.0 0.0"/>
      <geometry>
        <mesh filename="package://sobit_pro_description/meshes/head/head_camera_pan.stl" scale="0.001 0.001 0.001"/>
      </geometry>
      <material name="black"/>
    </visual>
    <collision>
      <origin rpy="0.0 0.0 0.0" xyz="0.0 0.0 0.022875"/>
      <geometry>
        <box size="0.0285 0.037 0.03525"/>
      </geometry>
    </collision>
    <inertial>
      <origin rpy="0.0 0.0 1.570796326795" xyz="0.0 0.0 0.022875"/>
      <mass value="0.08"/>
      <inertia ixx="1.3698749999999998e-05" ixy="0.0" ixz="0.0" iyy="1.7410416666666662e-05" iyz="0.0" izz="1.4541666666666667e-05"/>
    </inertial>
  </link>
  <joint name="head_tilt_joint" type="revolute">
    <parent link="head_pan_link"/>
    <child link="head_tilt_link"/>
    <origin rpy="0.0 0.0 0.0" xyz="0.0 0.0 0.0405"/>
    <axis xyz="0 -1 0"/>
    <limit effort="4.1" lower="-1.570796326795" upper="1.570796326795" velocity="4.796165"/>
  </joint>
  <link name="head_tilt_link">
    <visual>
      <origin rpy="0.0 0.0 1.570796326795" xyz="0.0 0.0 0.0"/>
      <geometry>
        <mesh filename="package://sobit_pro_description/meshes/head/head_camera_tilt.stl" scale="0.001 0.001 0.001"/>
      </geometry>
      <material name="black"/>
    </visual>
    <collision>
      <origin rpy="0.0 0.0 0.0" xyz="0.0 0.0 0.03375"/>
      <geometry>
        <box size="0.046 0.0466 0.0115"/>
      </geometry>
    </collision>
    <inertial>
      <origin rpy="0.0 0.0 0.0" xyz="0.0 0.0 0.03375"/>
      <mass value="0.08"/>
      <inertia ixx="1.4988333333333332e-05" ixy="0.0" ixz="0.0" iyy="1.5358733333333336e-05" iyz="0.0" izz="2.8583733333333332e-05"/>
    </inertial>
  </link>
  <transmission name="head_pan_joint_transmission">
    <type>transmission_interface/SimpleTransmission</type>
    <joint name="head_pan_joint">
      <hardwareInterface>hardware_interface/PositionJointInterface</hardwareInterface>
    </joint>
    <actuator name="head_pan_joint_actuator">
      <hardwareInterface>hardware_interface/PositionJointInterface</hardwareInterface>
      <mechanicalReduction>1</mechanicalReduction>
    </actuator>
  </transmission>
  <transmission name="head_tilt_joint_transmission">
    <type>transmission_interface/SimpleTransmission</type>
    <joint name="head_tilt_joint">
      <hardwareInterface>hardware_interface/PositionJointInterface</hardwareInterface>
    </joint>
    <actuator name="head_tilt_joint_actuator">
      <hardwareInterface>hardware_interface/PositionJointInterface</hardwareInterface>
      <mechanicalReduction>1</mechanicalReduction>
    </actuator>
  </transmission>
  <joint name="mic_base_joint" type="fixed">
    <parent link="back_base_link"/>
    <child link="mic_base_link"/>
    <origin rpy="0.0 0.0 0.0" xyz="0.0 0.0 0.5400"/>
  </joint>
  <link name="mic_base_link">
    <visual>
      <origin rpy="1.570796326795 0.0 3.14159265359" xyz="0.0 0.0 0.0"/>
      <geometry>
        <mesh filename="package://sobit_pro_description/meshes/sensor/mic_base.stl" scale="0.001 0.001 0.001"/>
      </geometry>
      <material name="black"/>
    </visual>
    <collision>
      <origin rpy="0.0 0.0 0.0" xyz="0.0 -0.054599999999999996 -0.01"/>
      <geometry>
        <box size="0.0292 0.12919999999999998 0.03"/>
      </geometry>
      <material name="black"/>
    </collision>
    <inertial>
      <origin rpy="0.0 0.0 0.0" xyz="0.0 -0.054599999999999996 -0.01"/>
      <!-- APPROX -->
      <mass value="0.15"/>
      <inertia ixx="2.1907999999999998e-05" ixy="0.0" ixz="0.0" iyy="0.00021990799999999994" iyz="0.0" izz="0.00021931599999999994"/>
    </inertial>
  </link>
  <joint name="mic_joint" type="fixed">
    <parent link="mic_base_link"/>
    <child link="mic_link"/>
    <origin rpy="0.0 0.0 0.0" xyz="0.0 -0.099 0.0240"/>
  </joint>
  <link name="mic_link">
    <visual>
      <origin rpy="1.570796326795 0.0 3.14159265359" xyz="0.0 0.0 0.0"/>
      <geometry>
        <mesh filename="package://sobit_pro_description/meshes/sensor/mic.stl" scale="0.001 0.001 0.001"/>
      </geometry>
      <material name="black"/>
    </visual>
    <collision>
      <origin rpy="0.0 1.1344640137963888 0.0" xyz="0.04911 -0.0056 0.0616"/>
      <geometry>
        <cylinder length="0.281" radius="0.011"/>
      </geometry>
      <material name="black"/>
    </collision>
    <inertial>
      <origin rpy="0.0 1.1344640137963888 0.0" xyz="0.04911 -0.0056 0.0616"/>
      <mass value="0.235"/>
      <inertia ixx="1.4217499999999997e-05" ixy="0.0" ixz="0.0" iyy="0.0015534283333333335" iyz="0.0" izz="0.0015534283333333335"/>
    </inertial>
  </link>
  <joint name="arm_base_joint" type="fixed">
    <parent link="plate_top_link"/>
    <child link="arm_base_link"/>
    <origin rpy="0.0 0.0 0.0" xyz="0.065 0.0 0.0"/>
  </joint>
  <link name="arm_base_link">
    <visual>
      <origin rpy="1.570796326795 0.0 0.0" xyz="0.0 0.0 0.0"/>
      <geometry>
        <mesh filename="package://sobit_pro_description/meshes/arm/arm_base.stl" scale="0.001 0.001 0.001"/>
      </geometry>
      <material name="black"/>
    </visual>
    <collision>
      <origin rpy="0.0 0.0 0.0" xyz="0.07 0.0 0.0215"/>
      <geometry>
        <box size="0.140 0.156 0.043"/>
      </geometry>
    </collision>
    <inertial>
      <origin rpy="0.0 0.0 1.570796326795" xyz="0.07 0.0 0.0215"/>
      <mass value="0.08"/>
      <inertia ixx="0.00014299333333333335" ixy="0.0" ixz="0.0" iyy="0.00017456666666666666" iyz="0.0" izz="0.00029290666666666665"/>
    </inertial>
  </link>
  <joint name="arm_shoulder_1_tilt_joint" type="revolute">
    <parent link="arm_base_link"/>
    <child link="arm_shoulder_1_tilt_link"/>
    <origin rpy="0.0 0.0 0.0 " xyz="0.1560 0.0 0.0215"/>
    <axis xyz="0.0 -1.0 0.0 "/>
    <limit effort="21.2" lower="-1.570796326795" upper="1.570796326795" velocity="11.031179004"/>
    <!-- <dynamics damping="0.2" friction="0" /> -->
  </joint>
  <link name="arm_shoulder_1_tilt_link">
    <visual>
      <origin rpy="1.570796326795 0.0 1.570796326795" xyz="0.0 0.0 0.0"/>
      <geometry>
        <mesh filename="package://sobit_pro_description/meshes/arm/arm_upper.stl" scale="0.001 0.001 0.001"/>
      </geometry>
      <material name="black"/>
    </visual>
    <collision>
      <origin rpy="0.0 0.0 0.0" xyz="0.0807 0.0 0.0"/>
      <geometry>
        <box size="0.1166 0.124 0.043"/>
      </geometry>
    </collision>
    <inertial>
      <origin rpy="0.0 0.0 1.570796326795" xyz="0.0807 0.0 0.0"/>
      <mass value="0.08"/>
      <inertia ixx="0.00010296373333333332" ixy="0.0" ixz="0.0" iyy="0.00011483333333333331" iyz="0.0" izz="0.00019314373333333333"/>
    </inertial>
  </link>
  <!-- <joint name="${prefix}_shoulder_2_tilt_joint" type="revolute" >
      <parent link="${prefix}_base_link" />
      <child link="${prefix}_shoulder_2_tilt_link" />
      <origin xyz="0.1560 0.0 0.0215" rpy="0.0 0.0 ${M_PI}" />
      <axis xyz="0.0 1.0 0.0 " />
      <mimic joint="${prefix}_shoulder_1_tilt_joint" multiplier="1" offset="0" />
      <limit lower="${-M_PI/2}" upper="${M_PI/2}" effort="${10.6*2}" velocity="11.031179004" />
      <dynamics damping="0.2" friction="0" />
    </joint> -->
  <!-- <link name="${prefix}_shoulder_2_tilt_link" /> -->
  <joint name="arm_elbow_upper_1_tilt_joint" type="revolute">
    <parent link="arm_shoulder_1_tilt_link"/>
    <child link="arm_elbow_upper_1_tilt_link"/>
    <origin rpy="0.0 0.0 0.0" xyz="0.1500 0.0 0.0"/>
    <axis xyz="0.0 -1.0 0.0 "/>
    <limit effort="8.2" lower="-1.570796326795" upper="1.570796326795" velocity="9.59233"/>
    <!-- <dynamics damping="0.2" friction="0" /> -->
  </joint>
  <link name="arm_elbow_upper_1_tilt_link">
    <visual>
      <origin rpy="1.570796326795 0.0 1.570796326795" xyz="0.0 0.0 0.0"/>
      <geometry>
        <mesh filename="package://sobit_pro_description/meshes/arm/arm_inner.stl" scale="0.001 0.001 0.001"/>
      </geometry>
      <material name="black"/>
    </visual>
    <collision>
      <origin rpy="0.0 0.0 0.0" xyz="0.0865 0.0 0.0"/>
      <geometry>
        <box size="0.127 0.048 0.035"/>
      </geometry>
    </collision>
    <inertial>
      <origin rpy="0.0 0.0 1.570796326795" xyz="0.0865 0.0 0.0"/>
      <mass value="0.08"/>
      <inertia ixx="0.00011569333333333334" ixy="0.0" ixz="0.0" iyy="2.3526666666666666e-05" iyz="0.0" izz="0.00012288666666666667"/>
    </inertial>
  </link>
  <!-- <joint name="${prefix}_elbow_upper_2_tilt_joint" type="revolute" >
      <parent link="${prefix}_shoulder_1_tilt_link" />
      <child link="${prefix}_elbow_upper_2_tilt_link" />
      <origin xyz="0.1500 0.0 0.0" rpy="0.0 0.0 ${M_PI}" />
      <axis xyz="0.0 1.0 0.0 " />
      <mimic joint="${prefix}_elbow_upper_1_tilt_joint" multiplier="1" offset="0" />
      <limit lower="${-M_PI/2}" upper="${M_PI/2}" effort="${4.1*2}" velocity="9.59233" />
      <dynamics damping="0.2" friction="0" />
    </joint> -->
  <!-- <link name="${prefix}_elbow_upper_2_tilt_link" /> -->
  <joint name="arm_elbow_lower_tilt_joint" type="revolute">
    <parent link="arm_elbow_upper_1_tilt_link"/>
    <child link="arm_elbow_lower_tilt_link"/>
    <origin rpy="0.0 0.0 0.0" xyz="0.1500 0.0 0.0"/>
    <axis xyz="0.0 -1.0 0.0 "/>
    <limit effort="4.1" lower="-1.570796326795" upper="1.570796326795" velocity="4.796165"/>
    <!-- <dynamics damping="0.2" friction="0" /> -->
  </joint>
  <link name="arm_elbow_lower_tilt_link">
    <visual>
      <origin rpy="1.570796326795 0.0 1.570796326795" xyz="0.0 0.0 0.0"/>
      <geometry>
        <mesh filename="package://sobit_pro_description/meshes/arm/arm_elbow_lower_tilt.stl" scale="0.001 0.001 0.001"/>
      </geometry>
      <material name="black"/>
    </visual>
    <collision>
      <origin rpy="0.0 0.0 0.0" xyz="0.025500000000000002 0.0 -0.0016249999999999997"/>
      <geometry>
        <box size="0.005 0.041 0.024"/>
      </geometry>
    </collision>
    <inertial>
      <origin rpy="0.0 0.0 1.570796326795" xyz="0.025500000000000002 0.0 -0.0016249999999999997"/>
      <mass value="0.08"/>
      <inertia ixx="4.006666666666666e-06" ixy="0.0" ixz="0.0" iyy="1.5046666666666668e-05" iyz="0.0" izz="1.1373333333333335e-05"/>
    </inertial>
  </link>
  <joint name="arm_elbow_lower_pan_joint" type="revolute">
    <parent link="arm_elbow_lower_tilt_link"/>
    <child link="arm_elbow_lower_pan_link"/>
    <origin rpy="0.0 0.0 0.0" xyz="0.028 0.0 0.0"/>
    <axis xyz="1.0 0.0 0.0 "/>
    <limit effort="4.1" lower="-1.570796326795" upper="1.570796326795" velocity="4.796165"/>
    <!-- <dynamics damping="0.2" friction="0" /> -->
  </joint>
  <link name="arm_elbow_lower_pan_link">
    <visual>
      <origin rpy="1.570796326795 0.0 1.570796326795" xyz="0.0 0.0 0.0"/>
      <geometry>
        <mesh filename="package://sobit_pro_description/meshes/arm/arm_elbow_lower_pan.stl" scale="0.001 0.001 0.001"/>
      </geometry>
      <material name="black"/>
    </visual>
    <collision>
      <origin rpy="0.0 0.0 0.0" xyz="0.062 0.0 -0.0016249999999999997"/>
      <geometry>
        <box size="0.120 0.048 0.03975"/>
      </geometry>
    </collision>
    <inertial>
      <origin rpy="0.0 0.0 1.570796326795" xyz="0.062 0.0 -0.0016249999999999997"/>
      <mass value="0.08"/>
      <inertia ixx="0.00010653374999999999" ixy="0.0" ixz="0.0" iyy="2.589375e-05" iyz="0.0" izz="0.00011135999999999999"/>
    </inertial>
  </link>
  <joint name="arm_wrist_tilt_joint" type="revolute">
    <parent link="arm_elbow_lower_pan_link"/>
    <child link="arm_wrist_tilt_link"/>
    <origin rpy="0.0 0.0 0.0" xyz="0.122009 0.0 0.0"/>
    <axis xyz="0.0 -1.0 0.0"/>
    <limit effort="4.1" lower="-1.570796326795" upper="1.570796326795" velocity="4.796165"/>
    <!-- <dynamics damping="0.2" friction="0" /> -->
  </joint>
  <link name="arm_wrist_tilt_link"/>
  <transmission name="arm_shoulder_1_tilt_joint_transmission">
    <type>transmission_interface/SimpleTransmission</type>
    <joint name="arm_shoulder_1_tilt_joint">
      <hardwareInterface>hardware_interface/PositionJointInterface</hardwareInterface>
    </joint>
    <actuator name="arm_shoulder_1_tilt_joint_actuator">
      <hardwareInterface>hardware_interface/PositionJointInterface</hardwareInterface>
      <mechanicalReduction>1</mechanicalReduction>
    </actuator>
  </transmission>
  <transmission name="arm_elbow_upper_1_tilt_joint_transmission">
    <type>transmission_interface/SimpleTransmission</type>
    <joint name="arm_elbow_upper_1_tilt_joint">
      <hardwareInterface>hardware_interface/PositionJointInterface</hardwareInterface>
    </joint>
    <actuator name="arm_elbow_upper_1_tilt_joint_actuator">
      <hardwareInterface>hardware_interface/PositionJointInterface</hardwareInterface>
      <mechanicalReduction>1</mechanicalReduction>
    </actuator>
  </transmission>
  <transmission name="arm_elbow_lower_tilt_joint_transmission">
    <type>transmission_interface/SimpleTransmission</type>
    <joint name="arm_elbow_lower_tilt_joint">
      <hardwareInterface>hardware_interface/PositionJointInterface</hardwareInterface>
    </joint>
    <actuator name="arm_elbow_lower_tilt_joint_actuator">
      <hardwareInterface>hardware_interface/PositionJointInterface</hardwareInterface>
      <mechanicalReduction>1</mechanicalReduction>
    </actuator>
  </transmission>
  <transmission name="arm_elbow_lower_pan_joint_transmission">
    <type>transmission_interface/SimpleTransmission</type>
    <joint name="arm_elbow_lower_pan_joint">
      <hardwareInterface>hardware_interface/PositionJointInterface</hardwareInterface>
    </joint>
    <actuator name="arm_elbow_lower_pan_joint_actuator">
      <hardwareInterface>hardware_interface/PositionJointInterface</hardwareInterface>
      <mechanicalReduction>1</mechanicalReduction>
    </actuator>
  </transmission>
  <transmission name="arm_wrist_tilt_joint_transmission">
    <type>transmission_interface/SimpleTransmission</type>
    <joint name="arm_wrist_tilt_joint">
      <hardwareInterface>hardware_interface/PositionJointInterface</hardwareInterface>
    </joint>
    <actuator name="arm_wrist_tilt_joint_actuator">
      <hardwareInterface>hardware_interface/PositionJointInterface</hardwareInterface>
      <mechanicalReduction>1</mechanicalReduction>
    </actuator>
  </transmission>
  <joint name="hand_base_joint" type="fixed">
    <parent link="arm_wrist_tilt_link"/>
    <child link="hand_base_link"/>
    <origin rpy="0.0 0.0 0.0" xyz="0.0 0.0 0.0"/>
  </joint>
  <link name="hand_base_link">
    <visual>
      <origin rpy="1.570796326795 0.0 1.570796326795" xyz="0.0 0.0 0.0"/>
      <geometry>
        <mesh filename="package://sobit_pro_description/meshes/hand/hand_base.stl" scale="0.001 0.001 0.001"/>
      </geometry>
      <material name="black"/>
    </visual>
    <collision>
      <origin rpy="0.0 0.0 0.0" xyz="0.052004999999999996 0.0 0.00425"/>
      <geometry>
        <box size="0.06102 0.102 0.0745"/>
      </geometry>
    </collision>
    <inertial>
      <origin rpy="0.0 0.0 1.570796326795" xyz="0.052004999999999996 0.0 0.00425"/>
      <mass value="0.08"/>
      <inertia ixx="6.182460266666666e-05" ixy="0.0" ixz="0.0" iyy="0.00010636166666666663" iyz="0.0" izz="9.418293599999999e-05"/>
    </inertial>
  </link>
  <joint name="hand_inner_l_joint" type="continuous">
    <parent link="hand_base_link"/>
    <child link="hand_inner_l_link"/>
    <origin rpy="0.0 0.0 0.0" xyz="0.0631932 0.0151495 0.0372231"/>
    <axis xyz="0.0 0.0 1.0"/>
    <mimic joint="hand_joint" multiplier="-1.0" offset="0"/>
  </joint>
  <link name="hand_inner_l_link">
    <visual>
      <origin rpy="0.0 0.0 1.570796326795" xyz="0.0 0.0 0.0"/>
      <geometry>
        <mesh filename="package://sobit_pro_description/meshes/hand/hand_inner_l.stl" scale="0.001 0.001 0.001"/>
      </geometry>
      <material name="black"/>
    </visual>
    <collision>
      <origin rpy="0.0 0.0 0.0" xyz="0.08057500000000001 0.0 -0.033"/>
      <geometry>
        <box size="0.05296 0.01 0.066"/>
      </geometry>
    </collision>
    <inertial>
      <origin rpy="0.0 0.0 1.570796326795" xyz="0.08057500000000001 0.0 -0.033"/>
      <mass value="0.08"/>
      <inertia ixx="4.773841066666667e-05" ixy="0.0" ixz="0.0" iyy="2.970666666666667e-05" iyz="0.0" izz="1.9365077333333332e-05"/>
    </inertial>
  </link>
  <joint name="hand_joint" type="revolute">
    <parent link="hand_base_link"/>
    <child link="hand_link"/>
    <origin rpy="0.0 0.0 0.0" xyz="0.0631932 -0.0151495 0.0372231"/>
    <axis xyz="0.0 0.0 1.0"/>
    <limit effort="4.1" lower="-1.570796326795" upper="0" velocity="4.796165"/>
  </joint>
  <link name="hand_link">
    <visual>
      <origin rpy="0.0 0.0 1.570796326795" xyz="0.0 0.0 0.0"/>
      <geometry>
        <mesh filename="package://sobit_pro_description/meshes/hand/hand_inner_r.stl" scale="0.001 0.001 0.001"/>
      </geometry>
      <material name="black"/>
    </visual>
    <collision>
      <origin rpy="0.0 0.0 0.0" xyz="0.08057500000000001 0.0 -0.033"/>
      <geometry>
        <box size="0.05296 0.01 0.066"/>
      </geometry>
    </collision>
    <inertial>
      <origin rpy="0.0 0.0 1.570796326795" xyz="0.08057500000000001 0.0 -0.033"/>
      <mass value="0.08"/>
      <inertia ixx="4.773841066666667e-05" ixy="0.0" ixz="0.0" iyy="2.970666666666667e-05" iyz="0.0" izz="1.9365077333333332e-05"/>
    </inertial>
  </link>
  <joint name="hand_outer_l_joint" type="continuous">
    <parent link="hand_base_link"/>
    <child link="hand_outer_l_link"/>
    <origin rpy="0.0 0.0 0.0" xyz="0.043193 0.04015 0.0282231"/>
    <axis xyz="0.0 0.0 1.0"/>
    <mimic joint="hand_inner_l_joint" multiplier="1.0" offset="0"/>
  </joint>
  <link name="hand_outer_l_link">
    <visual>
      <origin rpy="0.0 0.0 1.570796326795" xyz="0.0 0.0 0.0"/>
      <geometry>
        <mesh filename="package://sobit_pro_description/meshes/hand/hand_outer_l.stl" scale="0.001 0.001 0.001"/>
      </geometry>
      <material name="black"/>
    </visual>
    <collision>
      <origin rpy="0.0 0.0 0.0" xyz="0.082635 0.0 -0.028"/>
      <geometry>
        <box size="0.04281 0.01 0.056"/>
      </geometry>
    </collision>
    <inertial>
      <origin rpy="0.0 0.0 1.570796326795" xyz="0.082635 0.0 -0.028"/>
      <mass value="0.08"/>
      <inertia ixx="3.312464066666667e-05" ixy="0.0" ixz="0.0" iyy="2.1573333333333332e-05" iyz="0.0" izz="1.2884640666666666e-05"/>
    </inertial>
  </link>
  <joint name="hand_outer_r_joint" type="continuous">
    <parent link="hand_base_link"/>
    <child link="hand_outer_r_link"/>
    <origin rpy="0.0 0.0 0.0" xyz="0.043193 -0.04015 0.0282231"/>
    <axis xyz="0.0 0.0 1.0"/>
    <mimic joint="hand_joint" multiplier="1.0" offset="0"/>
  </joint>
  <link name="hand_outer_r_link">
    <visual>
      <origin rpy="0.0 0.0 1.570796326795" xyz="0.0 0.0 0.0"/>
      <geometry>
        <mesh filename="package://sobit_pro_description/meshes/hand/hand_outer_r.stl" scale="0.001 0.001 0.001"/>
      </geometry>
      <material name="black"/>
    </visual>
    <collision>
      <origin rpy="0.0 0.0 0.0" xyz="0.082635 0.0 -0.028"/>
      <geometry>
        <box size="0.04281 0.01 0.056"/>
      </geometry>
    </collision>
    <inertial>
      <origin rpy="0.0 0.0 1.570796326795" xyz="0.082635 0.0 -0.028"/>
      <mass value="0.08"/>
      <inertia ixx="3.312464066666667e-05" ixy="0.0" ixz="0.0" iyy="2.1573333333333332e-05" iyz="0.0" izz="1.2884640666666666e-05"/>
    </inertial>
  </link>
  <joint name="hand_finger_l_joint" type="continuous">
    <parent link="hand_inner_l_link"/>
    <child link="hand_finger_l_link"/>
    <origin rpy="0.0 0.0 0.0" xyz="0.114316 0.0 -0.027729"/>
    <axis xyz="0.0 0.0 1.0"/>
    <mimic joint="hand_joint" multiplier="1.0" offset="0"/>
  </joint>
  <link name="hand_finger_l_link">
    <visual>
      <origin rpy="0.0 0.0 1.570796326795" xyz="-0.029998 0.025 0.0"/>
      <geometry>
        <mesh filename="package://sobit_pro_description/meshes/hand/hand_finger_l.stl" scale="0.001 0.001 0.001"/>
      </geometry>
      <material name="black"/>
    </visual>
    <collision>
      <origin rpy="0.0 0.0 0.0" xyz="0.043656 0.0 -0.009"/>
      <geometry>
        <box size="0.07317 0.01137 0.044"/>
      </geometry>
    </collision>
    <inertial>
      <origin rpy="0.0 0.0 1.570796326795" xyz="0.043656 0.0 -0.009"/>
      <mass value="0.08"/>
      <inertia ixx="4.8598992666666664e-05" ixy="0.0" ixz="0.0" iyy="1.3768512666666664e-05" iyz="0.0" izz="3.655417199999999e-05"/>
    </inertial>
  </link>
  <joint name="hand_finger_r_joint" type="continuous">
    <parent link="hand_link"/>
    <child link="hand_finger_r_link"/>
    <origin rpy="0.0 0.0 0.0" xyz="0.114316 0.0 -0.027729"/>
    <axis xyz="0.0 0.0 1.0"/>
    <mimic joint="hand_joint" multiplier="-1.0" offset="0"/>
  </joint>
  <link name="hand_finger_r_link">
    <visual>
      <origin rpy="0.0 0.0 1.570796326795" xyz="-0.029998 -0.025 0.0"/>
      <geometry>
        <mesh filename="package://sobit_pro_description/meshes/hand/hand_finger_r.stl" scale="0.001 0.001 0.001"/>
      </geometry>
      <material name="black"/>
    </visual>
    <collision>
      <origin rpy="0.0 0.0 0.0" xyz="0.043656 0.0 -0.009"/>
      <geometry>
        <box size="0.07317 0.01137 0.044"/>
      </geometry>
    </collision>
    <inertial>
      <origin rpy="0.0 0.0 1.570796326795" xyz="0.043656 0.0 -0.009"/>
      <mass value="0.08"/>
      <inertia ixx="4.8598992666666664e-05" ixy="0.0" ixz="0.0" iyy="1.3768512666666664e-05" iyz="0.0" izz="3.655417199999999e-05"/>
    </inertial>
  </link>
  <transmission name="hand_joint_transmission">
    <type>transmission_interface/SimpleTransmission</type>
    <joint name="hand_joint">
      <hardwareInterface>hardware_interface/PositionJointInterface</hardwareInterface>
    </joint>
    <actuator name="hand_joint_actuator">
      <hardwareInterface>hardware_interface/PositionJointInterface</hardwareInterface>
      <mechanicalReduction>1</mechanicalReduction>
    </actuator>
  </transmission>
  <!-- <xacro:position_joint_transmission joint="${prefix_hand}_inner_l_joint" reduction="1" /> -->
  <!-- <xacro:position_joint_transmission joint="${prefix_hand}_inner_r_joint" reduction="1" /> -->
  <!-- <xacro:position_joint_transmission joint="${prefix_hand}_outer_l_joint" reduction="1" /> -->
  <!-- <xacro:position_joint_transmission joint="${prefix_hand}_outer_r_joint" reduction="1" /> -->
  <!-- <xacro:position_joint_transmission joint="${prefix_hand}_${prefix_finger}_l_joint" reduction="1" /> -->
  <!-- <xacro:position_joint_transmission joint="${prefix_hand}_${prefix_finger}_r_joint" reduction="1" /> -->
  <joint name="lidar_base_joint" type="fixed">
    <parent link="plate_bottom_link"/>
    <child link="lidar_base_link"/>
    <origin rpy="0.0 0.0 0.0" xyz="0.1500 0.0 0.0"/>
  </joint>
  <link name="lidar_base_link">
    <visual>
      <origin rpy="1.570796326795 0.0 3.14159265359" xyz="0.0 0.0 0.0"/>
      <geometry>
        <mesh filename="package://sobit_pro_description/meshes/sensor/lidar_base.stl" scale="0.001 0.001 0.001"/>
      </geometry>
      <material name="black"/>
    </visual>
    <collision>
      <origin rpy="0.0 0.0 0.0" xyz="0.046 0.0 -0.0035"/>
      <geometry>
        <box size="0.092 0.184 0.007"/>
      </geometry>
    </collision>
    <inertial>
      <origin rpy="0.0 0.0 0.0" xyz="0.046 0.0 -0.0035"/>
      <mass value="0.08"/>
      <inertia ixx="5.675333333333333e-05" ixy="0.0" ixz="0.0" iyy="0.00022603333333333332" iyz="0.0" izz="0.00028213333333333327"/>
    </inertial>
  </link>
  <joint name="lidar_laser_mount_joint" type="fixed">
    <origin rpy="0.0 0.0 0.0" xyz="0.067 0.0 0.0"/>
    <parent link="lidar_base_link"/>
    <child link="lidar_laser_mount"/>
  </joint>
  <link name="lidar_laser_mount">
    <visual>
      <origin rpy="0 0 0" xyz="0 0 0"/>
      <geometry>
        <!-- Origin of this mesh is the base of the bracket. -->
        <mesh filename="package://urg_node/meshes/hokuyo_ust.stl"/>
      </geometry>
      <material name="dark_grey"/>
    </visual>
  </link>
  <joint name="lidar_laser_joint" type="fixed">
    <!-- This offset is from the base of the bracket to the LIDAR's focal point. -->
    <origin rpy="0 0 0" xyz="0 0 0.0474"/>
    <parent link="lidar_laser_mount"/>
    <child link="lidar_laser"/>
  </joint>
  <link name="lidar_laser">
    <inertial>
      <mass value="1.3"/>
      <origin xyz="0 0 0"/>
      <inertia ixx="0.0036300318813199993" ixy="0.0" ixz="0.0" iyy="0.00369730685441" iyz="0.0" izz="0.0023214740714099995"/>
    </inertial>
  </link>
  <gazebo reference="lidar_laser">
    <turnGravityOff>true</turnGravityOff>
    <sensor name="lidar_laser" type="ray">
      <pose>0 0 0 0 0 0</pose>
      <visualize>False</visualize>
      <update_rate>1</update_rate>
      <ray>
        <scan>
          <horizontal>
            <samples>720</samples>
            <resolution>1</resolution>
            <min_angle>-1.570796326795</min_angle>
            <max_angle>1.570796326795</max_angle>
          </horizontal>
        </scan>
        <range>
          <min>0.1</min>
          <max>10.0</max>
          <resolution>0.01</resolution>
        </range>
        <noise>
          <type>gaussian</type>
          <mean>0.0</mean>
          <stddev>0.001</stddev>
        </noise>
      </ray>
      <plugin filename="libgazebo_ros_laser.so" name="gazebo_ros_laser">
        <topicName>scan</topicName>
        <frameName>sobit_pro/lidar_laser</frameName>
        <robotNamespace>/sobit_pro/</robotNamespace>
      </plugin>
    </sensor>
  </gazebo>
  <!-- <gazebo reference="${prefix}_laser_mount">
      <material>Gazebo/DarkGrey</material>
    </gazebo> -->
  <joint name="head_camera_joint" type="fixed">
    <parent link="head_tilt_link"/>
    <child link="head_camera_base"/>
    <origin rpy="0.0 0.0 0.0" xyz="-0.0065 0.0 0.0395"/>
  </joint>
  <link name="head_camera_base"/>
  <joint name="head_camera_plug_base_joint" type="fixed">
    <origin rpy="0 0 0" xyz="0.0 0 0.0"/>
    <parent link="head_camera_base"/>
    <child link="head_camera_plug_base_link"/>
  </joint>
  <link name="head_camera_plug_base_link">
    <visual>
      <origin rpy="0.0 0.0 0.0" xyz="0.0 0.0 0.0"/>
      <geometry>
        <mesh filename="package://azure_kinect_ros_driver/meshes/akdk_camera.dae"/>
      </geometry>
    </visual>
    <collision>
      <origin rpy="0.0 0.0 0.0" xyz="-0.013700000000000004 0.0 0.0111"/>
      <!-- <origin xyz="0.0 0.0 0.0" rpy="0.0 0.0 0.0" /> -->
      <geometry>
        <box size="0.0994 0.09637 0.0222"/>
        <!-- <mesh filename="package://azure_kinect_ros_driver/meshes/akdk_camera.dae" /> -->
      </geometry>
    </collision>
    <inertial>
      <origin rpy="0.0 0.0 0.0" xyz="-0.013700000000000004 0.0 0.0111"/>
      <mass value="0.440"/>
      <inertia ixx="0.0003803506666666667" ixy="0.0" ixz="0.0" iyy="0.00035860061966666665" iyz="0.0" izz="0.0007028096863333334"/>
      <!-- <inertia ixx="1.0" ixy="0.0" ixz="0.0"
                iyy="1.0" iyz="0.0"
                izz="1.0" /> -->
    </inertial>
  </link>
  <joint name="head_camera_visor_base_joint" type="fixed">
    <parent link="head_camera_plug_base_link"/>
    <child link="head_camera_visor_base_link"/>
    <origin rpy="0.0 0.0 0.0" xyz="0.062 0.0 0.005"/>
  </joint>
  <link name="head_camera_visor_base_link">
    <collision>
      <origin rpy="0.0 0.0 0.0" xyz="-0.013 0.0 0.0"/>
      <geometry>
        <box size="0.026 0.103 0.039"/>
      </geometry>
    </collision>
  </link>
  <!-- <joint name="${tf_prefix}depth_optical_joint" type="fixed">
      <parent link="${tf_prefix}visor_base_link" />
      <child link="${tf_prefix}depth_optical_link" />
      <origin xyz="0.0 0.0 0.0018" rpy="0.0 0.0 0.0" />
    </joint>

    <link name="${tf_prefix}depth_optical_link" /> -->
  <!-- <joint name="${tf_prefix}rgb_optical_joint" type="fixed">
      <parent link="${tf_prefix}visor_base_link" />
      <child link="${tf_prefix}rgb_optical_link" />
      <origin xyz="0.0 -0.0320 0.0" rpy="0.0 0.0 0.0" />
    </joint>

    <link name="${tf_prefix}rgb_optical_link" /> -->
  <joint name="matrix_board_joint" type="fixed">
    <parent link="head_camera_base"/>
    <child link="matrix_board_link"/>
    <origin rpy="0.0 0.0 0.0" xyz="-0.018625 0.0 0.023"/>
  </joint>
  <link name="matrix_board_link"/>
  <joint name="matrix_sensor_0_joint" type="fixed">
    <origin rpy="0.0 0.0 0.0" xyz="0.0 0.0 0.0"/>
    <parent link="matrix_board_link"/>
    <child link="matrix_sensor_0_link"/>
  </joint>
  <link name="matrix_sensor_0_link"/>
  <joint name="matrix_sensor_1_joint" type="fixed">
    <origin rpy="0.0 0.0 0.0" xyz="0.04 0.0 0.0"/>
    <parent link="matrix_board_link"/>
    <child link="matrix_sensor_1_link"/>
  </joint>
  <link name="matrix_sensor_1_link"/>
  <joint name="matrix_sensor_2_joint" type="fixed">
    <origin rpy="0.0 0.0 0.0" xyz="0.02 -0.034541 0.0"/>
    <parent link="matrix_board_link"/>
    <child link="matrix_sensor_2_link"/>
  </joint>
  <link name="matrix_sensor_2_link"/>
  <joint name="matrix_sensor_3_joint" type="fixed">
    <origin rpy="0.0 0.0 0.0" xyz="-0.02 -0.034541 0.0"/>
    <parent link="matrix_board_link"/>
    <child link="matrix_sensor_3_link"/>
  </joint>
  <link name="matrix_sensor_3_link"/>
  <joint name="matrix_sensor_4_joint" type="fixed">
    <origin rpy="0.0 0.0 0.0" xyz="-0.04 0.0 0.0"/>
    <parent link="matrix_board_link"/>
    <child link="matrix_sensor_4_link"/>
  </joint>
  <link name="matrix_sensor_4_link"/>
  <joint name="matrix_sensor_5_joint" type="fixed">
    <origin rpy="0.0 0.0 0.0" xyz="-0.02 0.034541 0.0"/>
    <parent link="matrix_board_link"/>
    <child link="matrix_sensor_5_link"/>
  </joint>
  <link name="matrix_sensor_5_link"/>
  <joint name="matrix_sensor_6_joint" type="fixed">
    <origin rpy="0.0 0.0 0.0" xyz="0.02 0.034541 0.0"/>
    <parent link="matrix_board_link"/>
    <child link="matrix_sensor_6_link"/>
  </joint>
  <link name="matrix_sensor_6_link"/>
  <joint name="hand_camera_base_joint" type="fixed">
    <origin rpy="0.0 0.0 0.0" xyz="0.0908687 0.0 -0.01539994"/>
    <parent link="arm_wrist_tilt_link"/>
    <child link="hand_camera_base_link"/>
  </joint>
  <link name="hand_camera_base_link"/>
  <!-- camera body, with origin at bottom screw mount -->
  <joint name="hand_camera_joint" type="fixed">
    <origin rpy="0.0 0.0 0.0" xyz="0.0 0.0 0.0"/>
    <parent link="hand_camera_base_link"/>
    <child link="hand_camera_bottom_screw_frame"/>
  </joint>
  <link name="hand_camera_bottom_screw_frame"/>
  <joint name="hand_camera_link_joint" type="fixed">
    <origin rpy="0 0 0" xyz="0.01085 0.009 0.021"/>
    <parent link="hand_camera_bottom_screw_frame"/>
    <child link="hand_camera_link"/>
  </joint>
  <link name="hand_camera_link">
    <visual>
      <!-- the mesh origin is at front plate in between the two infrared camera axes -->
      <origin rpy="0 0 1.570795" xyz="0.0038 -0.009 0"/>
      <geometry>
        <mesh filename="package://realsense2_description/meshes/d405.dae"/>
      </geometry>
    </visual>
    <collision>
      <origin rpy="0 0 0" xyz="-0.0077 -0.009 0"/>
      <!-- <origin xyz="0 ${-d405_cam_depth_py} 0" rpy="0 0 0"/> -->
      <geometry>
        <box size="0.023 0.042 0.042"/>
      </geometry>
    </collision>
    <inertial>
      <!-- The following are not reliable values, and should not be used for modeling -->
      <mass value="0.06"/>
      <origin rpy="0 0 0" xyz="-0.0077 -0.009 0"/>
      <inertia ixx="1.1464999999999998e-05" ixy="0.0" ixz="0.0" iyy="1.764e-05" iyz="0.0" izz="1.1464999999999998e-05"/>
    </inertial>
  </link>
  <!-- camera depth joints and links -->
  <joint name="hand_camera_depth_joint" type="fixed">
    <origin rpy="0 0 0" xyz="0 0 0"/>
    <parent link="hand_camera_link"/>
    <child link="hand_camera_depth_frame"/>
  </joint>
  <link name="hand_camera_depth_frame"/>
  <joint name="hand_camera_depth_optical_joint" type="fixed">
    <origin rpy="-1.570795 0 -1.570795" xyz="0 0 0"/>
    <parent link="hand_camera_depth_frame"/>
    <child link="hand_camera_depth_optical_frame"/>
  </joint>
  <link name="hand_camera_depth_optical_frame"/>
  <!-- camera left IR joints and links -->
  <joint name="hand_camera_infra1_joint" type="fixed">
    <origin rpy="0 0 0" xyz="0 0.0 0"/>
    <parent link="hand_camera_link"/>
    <child link="hand_camera_infra1_frame"/>
  </joint>
  <link name="hand_camera_infra1_frame"/>
  <joint name="hand_camera_infra1_optical_joint" type="fixed">
    <origin rpy="-1.570795 0 -1.570795" xyz="0 0 0"/>
    <parent link="hand_camera_infra1_frame"/>
    <child link="hand_camera_infra1_optical_frame"/>
  </joint>
  <link name="hand_camera_infra1_optical_frame"/>
  <!-- camera right IR joints and links -->
  <joint name="hand_camera_infra2_joint" type="fixed">
    <origin rpy="0 0 0" xyz="0 -0.018 0"/>
    <parent link="hand_camera_link"/>
    <child link="hand_camera_infra2_frame"/>
  </joint>
  <link name="hand_camera_infra2_frame"/>
  <joint name="hand_camera_infra2_optical_joint" type="fixed">
    <origin rpy="-1.570795 0 -1.570795" xyz="0 0 0"/>
    <parent link="hand_camera_infra2_frame"/>
    <child link="hand_camera_infra2_optical_frame"/>
  </joint>
  <link name="hand_camera_infra2_optical_frame"/>
  <!-- camera color joints and links -->
  <joint name="hand_camera_color_joint" type="fixed">
    <origin rpy="0 0 0" xyz="0 0.0 0"/>
    <parent link="hand_camera_link"/>
    <child link="hand_camera_color_frame"/>
  </joint>
  <link name="hand_camera_color_frame"/>
  <joint name="hand_camera_color_optical_joint" type="fixed">
    <origin rpy="-1.570795 0 -1.570795" xyz="0 0 0"/>
    <parent link="hand_camera_color_frame"/>
    <child link="hand_camera_color_optical_frame"/>
  </joint>
  <link name="hand_camera_color_optical_frame"/>
</robot>
